Workbook

Sheet 1-物料数据
A1: 物料编号 | B1: 物料名称 | C1: 关联半成品编号 | D1: 关联半成品名称 | E1: 包装类型 | F1: 生产周期 | G1: 粒径 | H1: 生产工艺(生产对标料型) | I1: 二级物料组 | J1: 三级物料组 | K1: 四级物料组 | L1: 加药标识 | M1: 加色标识
A2: 5000469 | B2: 海大牌罗非鱼配合饲料127-L40Φ3.0 | C2: 4000517 | D2: 127颗粒罗非鱼料配料半成品 | E2: 包料 | F2: 7 | G2: 3 | H2: 普通颗粒鱼料非超微2.6-3.5 | I2: 普水料 | J2: 罗非鱼 | K2: 颗粒料 | L2: 否 | M2: 否
A3: 5000495 | B3: 海大牌草鱼配合饲料101-L40Φ3.0 | C3: 4000517 | D3: 127颗粒罗非鱼料配料半成品 | E3: 包料 | F3: 7 | G3: 3 | H3: 普通颗粒鱼料非超微2.6-3.5 | I3: 普水料 | J3: 草鱼 | K3: 颗粒料 | L3: 否 | M3: 否
A4: 5000517 | B4: 海大牌草鱼配合饲料188-L40Φ3.0 | C4: 4081141 | D4: 666鱼种料配料半成品 | E4: 包料 | F4: 7 | G4: 3 | H4: 普通颗粒鱼料非超微2.6-3.5 | I4: 普水料 | J4: 草鱼 | K4: 颗粒料 | L4: 否 | M4: 否
A5: 5000611 | B5: 海大牌蛋鸭配合饲料933B-L40Φ3.8 | C5: 4000699 | D5: 612B红心蛋鸭料配料半成品 | E5: 包料 | F5: 4 | G5: 3.8 | H5: 颗粒鸭料>3.5 | I5: 禽料 | J5: 蛋鸭 | K5: 蛋鸭料 | L5: 否 | M5: 否
A6: 5000613 | B6: 海大牌蛋鸭配合饲料935B-L40Φ3.8 | C6: 4013466 | D6: 828B蛋鸭料半成品 | E6: 包料 | F6: 10 | G6: 3.8 | H6: 颗粒鸭料>3.5 | I6: 禽料 | J6: 蛋鸭 | K6: 蛋鸭料 | L6: 否 | M6: 否
A7: 5000618 | B7: 海恒牌蛋鸭配合饲料613B-L40Φ3.8 | C7: 4000705 | D7: 613B红心蛋鸭料配料半成品 | E7: 包料 | F7: 10 | G7: 3.8 | H7: 颗粒鸭料>3.5 | I7: 禽料 | J7: 蛋鸭 | K7: 蛋鸭料 | L7: 否 | M7: 否
A8: 5000632 | B8: 海大牌小鸭配合饲料901-L40Φ2.5 | C8: 4000679 | D8: 601小鸭料配料半成品 | E8: 包料 | F8: 7 | G8: 2.5 | H8: 颗粒鸭料≤2.5 | I8: 禽料 | J8: 番鸭/半番鸭 | K8: 小鸭料 | L8: 否 | M8: 否
A9: 5000633 | B9: 海恒牌小鸭配合饲料601-L40Φ2.5 | C9: 4000679 | D9: 601小鸭料配料半成品 | E9: 包料 | F9: 7 | G9: 2.5 | H9: 颗粒鸭料≤2.5 | I9: 禽料 | J9: 番鸭/半番鸭 | K9: 小鸭料 | L9: 否 | M9: 否
A10: 5000647 | B10: 海大牌肉鸭配合饲料906-L40Φ3.8 | C10: 4000693 | D10: 608肥鸭料配料半成品 | E10: 包料 | F10: 3 | G10: 3.8 | H10: 颗粒鸭料>3.5 | I10: 禽料 | J10: 番鸭/半番鸭 | K10: 大鸭料 | L10: 否 | M10: 否
A11: 5000652 | B11: 海恒牌肉鸭配合饲料235-L40Φ3.8 | C11: 4031438 | D11: 663肉鸭料配料半成品 | E11: 包料 | F11: 7 | G11: 3.8 | H11: 颗粒鸭料>3.5 | I11: 禽料 | J11: 白羽肉鸭 | K11: 大鸭料 | L11: 否 | M11: 否
A12: 5000653 | B12: 海恒牌番鸭配合饲料533-L40Φ3.8 | C12: 4011574 | D12: 533肉鸭料配料半成品 | E12: 包料 | F12: 7 | G12: 3.8 | H12: 颗粒鸭料>3.5 | I12: 禽料 | J12: 番鸭/半番鸭 | K12: 大鸭料 | L12: 否 | M12: 否
A13: 5000656 | B13: 海恒牌肉鸭配合饲料606-L40Φ3.8 | C13: 4075653 | D13: 203肉鸭料配料半成品 | E13: 包料 | F13: 7 | G13: 3.8 | H13: 颗粒鸭料>3.5 | I13: 禽料 | J13: 番鸭/半番鸭 | K13: 大鸭料 | L13: 否 | M13: 否
... A15: 5001186 | B15: 海大牌罗非鱼配合饲料225-L40Φ3.0 | C15: 4000937 | D15: 225颗粒罗非鱼料配料半成品 | E15: 包料 | F15: 7 | G15: 3 | H15: 普通颗粒鱼料非超微2.6-3.5 | I15: 普水料 | J15: 罗非鱼 | K15: 颗粒料 | L15: 否 | M15: 否
A16: 5013903 | B16: 海大牌鱼种配合饲料100A-1P40Φ1P | C16: 4011576 | D16: 100A鱼种料配料半成品 | E16: 包料 | F16: 5 | H16: 普通鱼料非超微0破 | I16: 普水料 | J16: 草鱼 | K16: 破碎料 | L16: 否 | M16: 否
A17: 5013904 | B17: 海大牌鱼种配合饲料100A-2P40Φ2P | C17: 4011576 | D17: 100A鱼种料配料半成品 | E17: 包料 | F17: 5 | H17: 普通鱼料非超微1破 | I17: 普水料 | J17: 草鱼 | K17: 破碎料 | L17: 否 | M17: 否
A18: 5013906 | B18: 海大牌鲮鱼配合饲料鲮鱼专用料-2P40Φ2P | C18: 4038247 | D18: 渔高丰2号配料半成品 | E18: 包料 | F18: 7 | H18: 普通鱼料非超微1破 | I18: 普水料 | J18: 鲮鱼 | K18: 破碎料 | L18: 否 | M18: 否
A19: 5013909 | B19: 海大牌鱼种配合饲料100A-L40Φ2.0 | C19: 4011576 | D19: 100A鱼种料配料半成品 | E19: 包料 | F19: 5 | G19: 2 | H19: 普通颗粒鱼料非超微1.6-2.5 | I19: 普水料 | J19: 草鱼 | K19: 颗粒料 | L19: 否 | M19: 否
A20: 5016078 | B20: 海大牌仔猪前期配合饲料诸多宝V1-L40Φ3.0 | C20: 4034088 | D20: HD01乳猪保育前期料配料半成品 | E20: 包料 | F20: 6 | G20: 3 | H20: 颗粒肉猪种猪包装>3.5 | I20: 猪料 | J20: 保育料 | K20: 保育前期料 | L20: 否 | M20: 否
A21: 5016103 | B21: 海大牌蛋鸭配合饲料828-L40Φ3.8 | C21: 4013465 | D21: 828蛋鸭料半成品 | E21: 包料 | F21: 7 | G21: 3.8 | H21: 颗粒鸭料>3.5 | I21: 禽料 | J21: 蛋鸭 | K21: 蛋鸭料 | L21: 否 | M21: 否
A22: 5016104 | B22: 海大牌蛋鸭配合饲料828B-L40Φ3.8 | C22: 4013466 | D22: 828B蛋鸭料半成品 | E22: 包料 | F22: 5 | G22: 3.8 | H22: 颗粒鸭料>3.5 | I22: 禽料 | J22: 蛋鸭 | K22: 蛋鸭料 | L22: 否 | M22: 否
A23: 5021724 | B23: 海恒牌肉鹅配合饲料702-L40Φ3.0 | C23: 4002087 | D23: 702肉鹅料配料半成品 | E23: 包料 | F23: 7 | G23: 3 | H23: 颗粒鹅料2.6-3.5 | I23: 禽料 | J23: 鹅料 | K23: 中鹅料 | L23: 否 | M23: 否
A24: 5022034 | B24: 海大牌淡水鱼配合饲料(鱼先丰)-L40Φ2.0 | C24: 4067508 | D24: 鱼先丰颗粒淡水鱼料配料半成品 | E24: 包料 | F24: 7 | G24: 2 | H24: 普通颗粒鱼料非超微1.6-2.5 | I24: 普水料 | J24: 鲫鱼 | K24: 颗粒料 | L24: 否 | M24: 否
A25: 5024958 | B25: 海大牌小猪配合饲料512-L40Φ3.8 | C25: 4019043 | D25: 512小猪料配料半成品 | E25: 包料 | F25: 2 | G25: 3.8 | H25: 颗粒肉猪种猪包装>3.5 | I25: 猪料 | J25: 肉猪料 | K25: 小猪料 | L25: 否 | M25: 否
A26: 5024959 | B26: 海大牌小猪配合饲料552-L40Φ3.8 | C26: 4001788 | D26: 552小猪料配料半成品 | E26: 包料 | F26: 2 | G26: 3.8 | H26: 颗粒肉猪种猪包装>3.5 | I26: 猪料 | J26: 肉猪料 | K26: 小猪料 | L26: 否 | M26: 否
A27: 5024961 | B27: 海大牌大猪配合饲料555A-L40Φ3.8 | C27: 4001786 | D27: 553中猪料配料半成品 | E27: 包料 | F27: 5 | G27: 3.8 | H27: 颗粒肉猪种猪包装>3.5 | I27: 猪料 | J27: 肉猪料 | K27: 大猪料 | L27: 否 | M27: 否
A28: 5029506 | B28: 海大牌肉鸭配合饲料209-L40Φ3.8 | C28: 4075653 | D28: 203肉鸭料配料半成品 | E28: 包料 | F28: 4 | G28: 3.8 | H28: 颗粒鸭料>3.5 | I28: 禽料 | J28: 番鸭/半番鸭 | K28: 大鸭料 | L28: 否 | M28: 否
A29: 5032125 | B29: 宏海牌草鱼配合饲料1602-2P40Φ2P | C29: 4000937 | D29: 225颗粒罗非鱼料配料半成品 | E29: 包料 | F29: 7 | H29: 普通鱼料非超微1破 | I29: 普水料 | J29: 草鱼 | K29: 破碎料 | L29: 否 | M29: 否
A30: 5032126 | B30: 宏海牌草鱼配合饲料1602-L40Φ3.0 | C30: 4000937 | D30: 225颗粒罗非鱼料配料半成品 | E30: 包料 | F30: 7 | G30: 3 | H30: 普通颗粒鱼料非超微2.6-3.5 | I30: 普水料 | J30: 草鱼 | K30: 颗粒料 | L30: 否 | M30: 否
A31: 5032620 | B31: 海大牌怀孕母猪配合饲料5G16-L40Φ3.8 | C31: 4034093 | D31: HD06怀孕母猪料配料半成品 | E31: 包料 | F31: 7 | G31: 3.8 | H31: 颗粒肉猪种猪包装>3.5 | I31: 猪料 | J31: 种猪料 | K31: 妊娠母猪料 | L31: 否 | M31: 否
A32: 5032621 | B32: 海大牌哺乳母猪配合饲料5G18-L40Φ3.8 | C32: 4034094 | D32: HD08哺乳母猪料配料半成品 | E32: 包料 | F32: 7 | G32: 3.8 | H32: 颗粒肉猪种猪包装>3.5 | I32: 猪料 | J32: 种猪料 | K32: 哺乳母猪料 | L32: 否 | M32: 否
A33: 5036676 | B33: 海大牌乳猪配合饲料5G11-L40Φ3.0(散装) | C33: 4003819 | D33: 111乳猪料配料半成品 | E33: 散料 | F33: 5 | G33: 3 | H33: 颗粒肉猪种猪散装≤3.5 | I33: 猪料 | J33: 保育料 | K33: 保育前期料 | L33: 否 | M33: 否
A34: 5036677 | B34: 海大牌小猪配合饲料5G12-L40Φ3.8(散装) | C34: 4072009 | D34: 小猪2号配料半成品 | E34: 散料 | F34: 5 | G34: 3.8 | H34: 颗粒肉猪种猪散装>3.5 | I34: 猪料 | J34: 肉猪料 | K34: 小猪料 | L34: 否 | M34: 否
A35: 5037904 | B35: 海大牌蛋鸭配合饲料935A-L40Φ3.8 | C35: 4030902 | D35: 935A红心蛋鸭料配料半成品 | E35: 包料 | F35: 4 | G35: 3.8 | H35: 颗粒鸭料>3.5 | I35: 禽料 | J35: 蛋鸭 | K35: 蛋鸭料 | L35: 否 | M35: 否
A36: 5040676 | B36: 海大牌种公猪配合饲料5G19-L40Φ3.8(散装) | C36: 4027844 | D36: 5G19种公猪料配料半成品 | E36: 包料 | F36: 7 | G36: 3.8 | H36: 颗粒肉猪种猪散装>3.5 | I36: 猪料 | J36: 种猪料 | K36: 种公猪料 | L36: 否 | M36: 否
A37: 5041384 | B37: 海大牌后备母猪配合饲料(HD05)-L40Φ3.5 | C37: 4019043 | D37: 512小猪料配料半成品 | E37: 包料 | F37: 4 | G37: 3.5 | H37: 颗粒肉猪种猪包装>3.5 | I37: 猪料 | J37: 种猪料 | K37: 后备前期料 | L37: 否 | M37: 否
A38: 5041385 | B38: 海大牌怀孕母猪配合饲料(HD06)-L40Φ3.5 | C38: 4034093 | D38: HD06怀孕母猪料配料半成品 | E38: 包料 | F38: 7 | G38: 3.5 | H38: 颗粒肉猪种猪包装>3.5 | I38: 猪料 | J38: 种猪料 | K38: 妊娠母猪料 | L38: 否 | M38: 否
A39: 5041386 | B39: 海大牌哺乳母猪配合饲料(HD08)-L40Φ3.5 | C39: 4034094 | D39: HD08哺乳母猪料配料半成品 | E39: 包料 | F39: 7 | G39: 3.5 | H39: 颗粒肉猪种猪包装>3.5 | I39: 猪料 | J39: 种猪料 | K39: 哺乳母猪料 | L39: 否 | M39: 否
A40: 5042789 | B40: 鑫生益牌蛋鸭配合饲料506H-L40Φ3.8 | C40: 4038956 | D40: 506H-红心蛋鸭配料半成品 | E40: 包料 | F40: 10 | G40: 3.8 | H40: 颗粒鸭料>3.5 | I40: 禽料 | J40: 蛋鸭 | K40: 蛋鸭料 | L40: 否 | M40: 否
A41: 5043653 | B41: 海大牌乳猪配合饲料(保育前期料HD01)L40Φ3.5 | C41: 4034088 | D41: HD01乳猪保育前期料配料半成品 | E41: 包料 | F41: 6 | G41: 3.5 | H41: 颗粒肉猪种猪包装≤3.5 | I41: 猪料 | J41: 保育料 | K41: 保育前期料 | L41: 否 | M41: 否
...

Sheet 2-供需数据
A1: 物料编号 | B1: 物料名称 | C1: 产品分类 | D1: T需求 | E1: T+1需求 | F1: T+2需求 | G1: T+3需求 | H1: T+4需求 | I1: T+5需求 | J1: T+6需求 | K1: T+7需求 | L1: 供应 | M1: 库存最大值 | N1: 库存最小值 | O1: 前7天日均销量 | P1: 前30天日均销量
A2: 5000469 | B2: =VLOOKUP(A:A,'1-物料数据'!A:B,2,FALSE) -> 海大牌罗非鱼配合饲料127-L40Φ3.0 | C2: 非常规2 | D2: 2.4 | E2: 0 | F2: 0 | G2: 0 | H2: 0 | I2: 0 | J2: 0 | K2: 0 | L2: 15.12 | M2: 0 | N2: 0 | O2: 0.34 | P2: 0.88
A3: 5000495 | B3: =VLOOKUP(A:A,'1-物料数据'!A:B,2,FALSE) -> 海大牌草鱼配合饲料101-L40Φ3.0 | C3: 非常规2 | D3: 0 | E3: 0 | F3: 0 | G3: 0 | H3: 0 | I3: 0 | J3: 0 | K3: 0 | L3: 14.16 | M3: 0 | N3: 0 | O3: 2.62 | P3: 1.31
A4: 5000517 | B4: =VLOOKUP(A:A,'1-物料数据'!A:B,2,FALSE) -> 海大牌草鱼配合饲料188-L40Φ3.0 | C4: 非常规2 | D4: 0 | E4: 0 | F4: 0 | G4: 0 | H4: 0 | I4: 0 | J4: 0 | K4: 0 | L4: 13.2 | M4: 0 | N4: 0 | O4: 0 | P4: 0.17
A5: 5000611 | B5: =VLOOKUP(A:A,'1-物料数据'!A:B,2,FALSE) -> 海大牌蛋鸭配合饲料933B-L40Φ3.8 | C5: 常规1 | D5: 24 | E5: 0 | F5: 0 | G5: 0 | H5: 0 | I5: 0 | J5: 0 | K5: 0 | L5: 26.52 | M5: 60 | N5: 32 | O5: 21.07 | P5: 26.69
A6: 5000613 | B6: =VLOOKUP(A:A,'1-物料数据'!A:B,2,FALSE) -> 海大牌蛋鸭配合饲料935B-L40Φ3.8 | C6: 非常规1 | D6: 0 | E6: 0 | F6: 0 | G6: 0 | H6: 0 | I6: 0 | J6: 0 | K6: 0 | L6: 0 | M6: 0 | N6: 0 | O6: 0 | P6: 0
A7: 5000618 | B7: =VLOOKUP(A:A,'1-物料数据'!A:B,2,FALSE) -> 海恒牌蛋鸭配合饲料613B-L40Φ3.8 | C7: 非常规1 | D7: 0 | E7: 0 | F7: 0 | G7: 0 | H7: 0 | I7: 0 | J7: 0 | K7: 0 | L7: 0 | M7: 44 | N7: 0 | O7: 0 | P7: 0
A8: 5000632 | B8: =VLOOKUP(A:A,'1-物料数据'!A:B,2,FALSE) -> 海大牌小鸭配合饲料901-L40Φ2.5 | C8: 常规2 | D8: 6.28 | E8: 0 | F8: 0 | G8: 0 | H8: 0 | I8: 0 | J8: 0 | K8: 0 | L8: 13.48 | M8: 26 | N8: 16 | O8: 7.13 | P8: 5.39
A9: 5000633 | B9: =VLOOKUP(A:A,'1-物料数据'!A:B,2,FALSE) -> 海恒牌小鸭配合饲料601-L40Φ2.5 | C9: 常规2 | D9: 6.8 | E9: 0 | F9: 0 | G9: 0 | H9: 0 | I9: 0 | J9: 0 | K9: 0 | L9: 22.28 | M9: 40 | N9: 20 | O9: 9.53 | P9: 8.35
A10: 5000647 | B10: =VLOOKUP(A:A,'1-物料数据'!A:B,2,FALSE) -> 海大牌肉鸭配合饲料906-L40Φ3.8 | C10: 常规1 | D10: 12 | E10: 0 | F10: 0 | G10: 0 | H10: 0 | I10: 0 | J10: 0 | K10: 0 | L10: 25.24 | M10: 60 | N10: 32 | O10: 20.97 | P10: 18.46
A11: 5000648 | B11: 海大牌肉鸭配合饲料908-L40Φ3.8 | C11: 常规2 | D11: 36.2 | E11: 0 | F11: 0 | G11: 0 | H11: 0 | I11: 0 | J11: 0 | K11: 0 | L11: 45.04 | M11: 40 | N11: 20 | O11: 8.11 | P11: 9.28
A12: 5000652 | B12: =VLOOKUP(A:A,'1-物料数据'!A:B,2,FALSE) -> 海恒牌肉鸭配合饲料235-L40Φ3.8 | C12: 非常规1 | D12: 0 | E12: 17.2 | F12: 0 | G12: 0 | H12: 0 | I12: 0 | J12: 0 | K12: 0 | L12: 13.88 | M12: 0 | N12: 0 | O12: 8.79 | P12: 10.96
A13: 5000653 | B13: =VLOOKUP(A:A,'1-物料数据'!A:B,2,FALSE) -> 海恒牌番鸭配合饲料533-L40Φ3.8 | C13: 常规2 | D13: 30.8 | E13: 0 | F13: 0 | G13: 0 | H13: 0 | I13: 0 | J13: 0 | K13: 0 | L13: 53.56 | M13: 88 | N13: 24 | O13: 20.57 | P13: 22.85
A14: 5000654 | B14: 海恒牌肉鸭配合饲料538-L40Φ3.8 | C14: 常规1 | D14: 0 | E14: 0 | F14: 0 | G14: 0 | H14: 0 | I14: 0 | J14: 0 | K14: 0 | L14: 34.72 | M14: 60 | N14: 32 | O14: 16.27 | P14: 15.45
A15: 5000656 | B15: =VLOOKUP(A:A,'1-物料数据'!A:B,2,FALSE) -> 海恒牌肉鸭配合饲料606-L40Φ3.8 | C15: 非常规1 | D15: 6 | E15: 6 | F15: 6 | G15: 0 | H15: 0 | I15: 0 | J15: 0 | K15: 0 | L15: 50.96 | M15: 33 | N15: 0 | O15: 12.32 | P15: 10.03
A16: 5000658 | B16: 海恒牌肉鸭配合饲料608-L40Φ3.8 | C16: 常规1 | D16: 53.32 | E16: 0 | F16: 0 | G16: 0 | H16: 0 | I16: 0 | J16: 0 | K16: 0 | L16: 127.16 | M16: 200 | N16: 89 | O16: 81.98 | P16: 88.95
A17: 5000659 | B17: =VLOOKUP(A:A,'1-物料数据'!A:B,2,FALSE) -> 海恒牌肉鸭配合饲料688-L40Φ3.8 | C17: 常规1 | D17: 82.2 | E17: 0 | F17: 0 | G17: 0 | H17: 0 | I17: 0 | J17: 0 | K17: 0 | L17: 141.56 | M17: 120 | N17: 60 | O17: 53.78 | P17: 61.89
A18: 5001186 | B18: =VLOOKUP(A:A,'1-物料数据'!A:B,2,FALSE) -> 海大牌罗非鱼配合饲料225-L40Φ3.0 | C18: 非常规2 | D18: 16 | E18: 0 | F18: 0 | G18: 0 | H18: 0 | I18: 0 | J18: 0 | K18: 0 | L18: 30.88 | M18: 0 | N18: 0 | O18: 2.69 | P18: 3.01
A19: 5013903 | B19: =VLOOKUP(A:A,'1-物料数据'!A:B,2,FALSE) -> 海大牌鱼种配合饲料100A-1P40Φ1P | C19: 非常规2 | D19: 9.84 | E19: 0 | F19: 0 | G19: 0 | H19: 0 | I19: 0 | J19: 0 | K19: 0 | L19: 47.8 | M19: 0 | N19: 0 | O19: 6.58 | P19: 5.95
A20: 5013904 | B20: =VLOOKUP(A:A,'1-物料数据'!A:B,2,FALSE) -> 海大牌鱼种配合饲料100A-2P40Φ2P | C20: 非常规2 | D20: 1.04 | E20: 0 | F20: 0 | G20: 0 | H20: 0 | I20: 0 | J20: 0 | K20: 0 | L20: 10.76 | M20: 172 | N20: 0 | O20: 1.53 | P20: 1.12
A21: 5013906 | B21: =VLOOKUP(A:A,'1-物料数据'!A:B,2,FALSE) -> 海大牌鲮鱼配合饲料鲮鱼专用料-2P40Φ2P | C21: 非常规2 | D21: 0.6 | E21: 0 | F21: 0 | G21: 0 | H21: 0 | I21: 0 | J21: 0 | K21: 0 | L21: 9.88 | M21: 4 | N21: 0 | O21: 0.43 | P21: 0.28
A22: 5013909 | B22: =VLOOKUP(A:A,'1-物料数据'!A:B,2,FALSE) -> 海大牌鱼种配合饲料100A-L40Φ2.0 | C22: 非常规2 | D22: 0 | E22: 0 | F22: 0 | G22: 0 | H22: 0 | I22: 0 | J22: 0 | K22: 0 | L22: 17.16 | M22: 0 | N22: 0 | O22: 1.74 | P22: 2
A23: 5016078 | B23: =VLOOKUP(A:A,'1-物料数据'!A:B,2,FALSE) -> 海大牌仔猪前期配合饲料诸多宝V1-L40Φ3.0 | C23: 非常规1 | D23: 13.8 | E23: 0 | F23: 0 | G23: 0 | H23: 0 | I23: 0 | J23: 0 | K23: 0 | L23: 24.2 | M23: 24 | N23: 0 | O23: 4.32 | P23: 4.62
A24: 5016104 | B24: =VLOOKUP(A:A,'1-物料数据'!A:B,2,FALSE) -> 海大牌蛋鸭配合饲料828B-L40Φ3.8 | C24: 常规2 | D24: 18 | E24: 0 | F24: 0 | G24: 0 | H24: 0 | I24: 0 | J24: 0 | K24: 0 | L24: 3.6 | M24: 44 | N24: 20 | O24: 6.13 | P24: 9.86
A25: 5022034 | B25: =VLOOKUP(A:A,'1-物料数据'!A:B,2,FALSE) -> 海大牌淡水鱼配合饲料(鱼先丰)-L40Φ2.0 | C25: 非常规2 | D25: 0 | E25: 0 | F25: 0 | G25: 0 | H25: 0 | I25: 0 | J25: 0 | K25: 0 | L25: 2.12 | M25: 0 | N25: 0 | O25: 4.46 | P25: 4.03
A26: 5024959 | B26: =VLOOKUP(A:A,'1-物料数据'!A:B,2,FALSE) -> 海大牌小猪配合饲料552-L40Φ3.8 | C26: 常规1 | D26: 35 | E26: 0 | F26: 12 | G26: 0 | H26: 0 | I26: 0 | J26: 0 | K26: 0 | L26: 27.04 | M26: 52 | N26: 20 | O26: 21.59 | P26: 20.88
A27: 5024961 | B27: =VLOOKUP(A:A,'1-物料数据'!A:B,2,FALSE) -> 海大牌大猪配合饲料555A-L40Φ3.8 | C27: 常规1 | D27: 15.6 | E27: 0 | F27: 0 | G27: 0 | H27: 0 | I27: 0 | J27: 0 | K27: 0 | L27: 39.12 | M27: 44 | N27: 20 | O27: 13.26 | P27: 14.45
A28: 5029505 | B28: 海大牌肉鸭配合饲料203-L40Φ3.8 | C28: 常规2 | D28: 0 | E28: 0 | F28: 0 | G28: 0 | H28: 0 | I28: 0 | J28: 0 | K28: 0 | L28: 0 | M28: 40 | N28: 20 | O28: 0 | P28: 0.17
A29: 5029506 | B29: =VLOOKUP(A:A,'1-物料数据'!A:B,2,FALSE) -> 海大牌肉鸭配合饲料209-L40Φ3.8 | C29: 非常规1 | D29: 26.8 | E29: 0 | F29: 0 | G29: 0 | H29: 0 | I29: 0 | J29: 0 | K29: 0 | L29: 71.84 | M29: 36 | N29: 0 | O29: 17.3 | P29: 15.94
A30: 5032125 | B30: =VLOOKUP(A:A,'1-物料数据'!A:B,2,FALSE) -> 宏海牌草鱼配合饲料1602-2P40Φ2P | C30: 非常规2 | D30: 0 | E30: 0 | F30: 0 | G30: 0 | H30: 0 | I30: 0 | J30: 0 | K30: 0 | L30: 5.56 | M30: 0 | N30: 0 | O30: 0.34 | P30: 0.5
A31: 5032126 | B31: =VLOOKUP(A:A,'1-物料数据'!A:B,2,FALSE) -> 宏海牌草鱼配合饲料1602-L40Φ3.0 | C31: 非常规2 | D31: 0 | E31: 0 | F31: 0 | G31: 0 | H31: 0 | I31: 0 | J31: 0 | K31: 0 | L31: 1.44 | M31: 0 | N31: 0 | O31: 1 | P31: 0.77
A32: 5032620 | B32: =VLOOKUP(A:A,'1-物料数据'!A:B,2,FALSE) -> 海大牌怀孕母猪配合饲料5G16-L40Φ3.8 | C32: 非常规1 | D32: 7.92 | E32: 0 | F32: 0 | G32: 0 | H32: 0 | I32: 0 | J32: 0 | K32: 0 | L32: 11 | M32: 24 | N32: 0 | O32: 3.06 | P32: 3.17
A33: 5032621 | B33: =VLOOKUP(A:A,'1-物料数据'!A:B,2,FALSE) -> 海大牌哺乳母猪配合饲料5G18-L40Φ3.8 | C33: 非常规1 | D33: 4.12 | E33: 0 | F33: 0 | G33: 0 | H33: 0 | I33: 0 | J33: 0 | K33: 0 | L33: 5.92 | M33: 12 | N33: 0 | O33: 1.48 | P33: 1.56
A34: 5036676 | B34: =VLOOKUP(A:A,'1-物料数据'!A:B,2,FALSE) -> 海大牌乳猪配合饲料5G11-L40Φ3.0(散装) | C34: 非常规2 | D34: 0 | E34: 0 | F34: 0 | G34: 0 | H34: 0 | I34: 0 | J34: 0 | K34: 0 | L34: 0 | M34: 0 | N34: 0 | O34: 0.57 | P34: 0.87
A35: 5036677 | B35: =VLOOKUP(A:A,'1-物料数据'!A:B,2,FALSE) -> 海大牌小猪配合饲料5G12-L40Φ3.8(散装) | C35: 非常规2 | D35: 0 | E35: 0 | F35: 0 | G35: 0 | H35: 0 | I35: 0 | J35: 0 | K35: 0 | L35: 0.48 | M35: 0 | N35: 0 | O35: 3.03 | P35: 1.6
A36: 5037473 | B36: 久和牌肉鸭配合饲料663-L40Φ3.8 | C36: 常规1 | D36: 28.8 | E36: 0 | F36: 0 | G36: 0 | H36: 0 | I36: 0 | J36: 0 | K36: 0 | L36: 73.08 | M36: 200 | N36: 80 | O36: 55.93 | P36: 57.47
A37: 5037474 | B37: 久和牌肉鸭配合饲料665-L40Φ3.8 | C37: 非常规1 | D37: 0 | E37: 0 | F37: 0 | G37: 0 | H37: 0 | I37: 0 | J37: 0 | K37: 0 | L37: 0 | M37: 0 | N37: 0 | O37: 0 | P37: 0
A38: 5037904 | B38: =VLOOKUP(A:A,'1-物料数据'!A:B,2,FALSE) -> 海大牌蛋鸭配合饲料935A-L40Φ3.8 | C38: 常规1 | D38: 52 | E38: 8 | F38: 0 | G38: 0 | H38: 0 | I38: 0 | J38: 0 | K38: 0 | L38: 76.28 | M38: 132 | N38: 60 | O38: 88.83 | P38: 84.49
A39: 5040676 | B39: =VLOOKUP(A:A,'1-物料数据'!A:B,2,FALSE) -> 海大牌种公猪配合饲料5G19-L40Φ3.8(散装) | C39: 非常规2 | D39: 0 | E39: 0 | F39: 0 | G39: 0 | H39: 0 | I39: 0 | J39: 0 | K39: 0 | L39: 0 | M39: 0 | N39: 0 | O39: 0 | P39: 0
A40: 5041384 | B40: =VLOOKUP(A:A,'1-物料数据'!A:B,2,FALSE) -> 海大牌后备母猪配合饲料(HD05)-L40Φ3.5 | C40: 非常规1 | D40: 0 | E40: 0 | F40: 0 | G40: 0 | H40: 0 | I40: 0 | J40: 0 | K40: 0 | L40: 0 | M40: 0 | N40: 0 | O40: 0.2 | P40: 0.12
...

Sheet 3-前置订单数据
A1: 生产订单号 | B1: 车间 | C1: 产线 | D1: 物料 | E1: 计划产量 | F1: 已完工产量 | G1: 继续生产量 | H1: 是否上次末产品
A2: 106732936 | B2: 一车间 | C2: 二号线 | D2: 5082213 | E2: 96.8 | F2: 33.6 | G2: 63.2 | H2: 是

Sheet 4-上次末生产物料
A1: 车间 | B1: 产线 | C1: 上次末生产物料
A2: 一车间 | B2: 一号线 | C2: 5037473
A3: 一车间 | B3: 二号线 | C3: 5082213
A4: 一车间 | B4: 三号线 | C4: 5082211
A5: 一车间 | B5: 四号线 | C5: 5000659
A6: 二车间 | B6: 五号线 | C6: 5078546
A7: 二车间 | B7: 六号线 | C7: 5043653
A8: 二车间 | B8: 七号线 | C8: 5000658

Sheet 5-产线数据
A1: 产线编号 | B1: 产线名称 | C1: 所属车间 | D1: 混合机整数倍 | E1: 预估产能 | F1: 额外开班时长（小时）
A2: 7 | B2: 七号线 | C2: 一车间 | D2: 4 | F2: 2
A3: 6 | B3: 六号线 | C3: 二车间 | D3: 4 | F3: 2
A4: 5 | B4: 五号线 | C4: 二车间 | D4: 4 | F4: 2
A5: 4 | B5: 四号线 | C5: 一车间 | D5: 2.2 | F5: 2
A6: 3 | B6: 三号线 | C6: 一车间 | D6: 2.2 | F6: 2
A7: 2 | B7: 二号线 | C7: 一车间 | D7: 2.2 | F7: 2
A8: 1 | B8: 一号线 | C8: 一车间 | D8: 2.2 | F8: 2

Sheet 6-产能数据
A1: 物料 | B1: 产线编号 | C1: 产能 | D1: 排产优先级
A2: 5013905 | B2: 3 | C2: 5 | D2: 0
A3: 5044593 | B3: 3 | C3: 10 | D3: 3
A4: 5044598 | B4: 3 | C4: 10 | D4: 3
A5: 5049173 | B5: 3 | C5: 6 | D5: 1
A6: 5064279 | B6: 3 | C6: 10 | D6: 3
A7: 5089936 | B7: 3 | C7: 5 | D7: 0
A8: 5089937 | B8: 3 | C8: 6 | D8: 1
A9: 5000469 | B9: 3 | C9: 10 | D9: 3
A10: 5000495 | B10: 3 | C10: 10 | D10: 3
A11: 5000517 | B11: 3 | C11: 10 | D11: 3
A12: 5001186 | B12: 3 | C12: 10 | D12: 3
A13: 5013903 | B13: 3 | C13: 5 | D13: 0
... A281: 5117558 | B281: 2 | C281: 13 | D281: 0

Sheet 车间班次
A1: 车间 | B1: 班次 | C1: 开始时间 | D1: 结束时间
A2: 一车间 | B2: 早班 | C2: 08：00 | D2: 20：00 | E2: 班次说明：先开晚班，再开白班
A3: 一车间 | B3: 晚班 | C3: 20：00 | D3: 08：00
A4: 二车间 | B4: 早班 | C4: 08：00 | D4: 20：00
A5: 二车间 | B5: 晚班 | C5: 20：00 | D5: 08：00

Sheet 换型规则
A1: 物料组二级 | B1: 换型规则
A2: 猪料、普水料 | B2: 当前物料与上一个物料，对比下列几个基础属性，存在不相同的则需要切换，取对应换型时长；若存在多个属性不相同，则取最大的换型时长： 1. 粒径：30分钟 2. 半成品：20分钟 3. 二级物料组：60分钟 4. 三级物料组：60分钟 如果存在加药、加色的情况，需要额外增加20分钟换型时长
A3: 禽料 | B3: 当前物料与上一个物料，对比下列几个基础属性，存在不相同的则需要切换，取对应换型时长；若存在多个属性不相同，则取最大的换型时长： 1. 粒径：30分钟 2. 半成品：20分钟 3. 二级物料组：60分钟 4. 四级物料组：45分钟 如果存在加药、加色的情况，需要额外增加20分钟换型时长

Sheet 字段说明
A1: 字段 | B1: 说明
A2: 物料编号 | B2: 成品物料编号
A3: 物料名称 | B3: 成品物料名称
A4: 关联半成品编号 | B4: 成品物料所对应的半成品物料编号
A5: 关联半成品名称 | B5: 成品物料所对应的半成品物料名称
A6: 包装类型 | B6: 区分成品物料是袋装包料，还是无包装散料，核心取值：包料、散料
A7: 生产周期 | B7: 物料重复生产的间隔周期，多久生产一次该物料
A8: 粒径 | B8: 成品物料颗粒大小，若为空则是破碎料
A9: 生产工艺(生产对标料型) | B9: 物料对应的料型与粒径工艺标准
A10: 二级物料组 | B10: 所属物料二级
A11: 三级物料组 | B11: 所属物料三级
A12: 四级物料组 | B12: 所属物料四级
... A44: 排产优先级 | B44: 同一个物料可以在多条产线生产时，优先排在哪条产线生产，数字越小，优先级越高
